#VRML_SIM R2025a utf8

EXTERNPROTO "https://raw.githubusercontent.com/cyberbotics/webots/R2025a/projects/objects/backgrounds/protos/TexturedBackground.proto"
EXTERNPROTO "https://raw.githubusercontent.com/cyberbotics/webots/R2025a/projects/objects/backgrounds/protos/TexturedBackgroundLight.proto"
EXTERNPROTO "https://raw.githubusercontent.com/cyberbotics/webots/R2025a/projects/objects/floors/protos/RectangleArena.proto"
EXTERNPROTO "https://raw.githubusercontent.com/cyberbotics/webots/R2025a/projects/appearances/protos/Parquetry.proto"

WorldInfo {
}
Viewpoint {
  orientation -0.21456775990670812 0.19678007241438064 0.9566808660724894 1.5954006116980857
  position 0.026661100732645503 -2.0490793648608054 1.0293337391072566
}
TexturedBackground {
}
TexturedBackgroundLight {
}
RectangleArena {
  floorAppearance Parquetry {
    type "light strip"
  }
}
Robot {
  translation -0.22 0 0.09
  rotation 0 1 0 5.307156870259904e-06
  children [
    HingeJoint {
      jointParameters HingeJointParameters {
        axis 0 0 1
      }
      device [
        RotationalMotor {
          name "motor1"
        }
      ]
      endPoint Solid {
        translation 0 0 0.00999999999999998
        children [
          HingeJoint {
            jointParameters HingeJointParameters {
              axis 0 1 0
              anchor 0 0 0.0379
            }
            device [
              RotationalMotor {
                name "motor2"
              }
            ]
            endPoint Solid {
              translation -2.481541837659083e-24 0 1.3877787807814457e-17
              rotation 0 1 0 0
              children [
                HingeJoint {
                  jointParameters HingeJointParameters {
                    axis 0 1 0
                    anchor 0.03 0 0.274715
                  }
                  device [
                    RotationalMotor {
                      name "motor3"
                    }
                  ]
                  endPoint Solid {
                    translation 0.030000007079618068 -1.951099498296675e-11 0.27471392567579755
                    rotation 0.9999966234097578 0.0025986790213595326 6.035497727082773e-06 1.0145929175942769e-06
                    children [
                      HingeJoint {
                        jointParameters HingeJointParameters {
                          axis 0 0 1
                          anchor 0.216 0 -0.0027
                        }
                        device [
                          RotationalMotor {
                            name "motor4"
                          }
                        ]
                        endPoint Solid {
                          translation 0.21600000065933503 -7.743655684634297e-13 -0.002700171835538112
                          children [
                            Shape {
                              appearance PBRAppearance {
                                baseColor 0.505882 0.505882 0.505882
                                metalness 0
                              }
                              geometry Mesh {
                                url [
                                  "../meshes/Wrist_4_motor_washer.STL"
                                ]
                              }
                            }
                            Shape {
                              appearance PBRAppearance {
                                baseColor 0.196078 0.196078 0.196078
                                metalness 0
                              }
                              geometry Mesh {
                                url [
                                  "../meshes/Wrist_4_motor_washer_gripper.STL"
                                ]
                              }
                            }
                          ]
                          boundingObject Pose {
                            translation 0.0423 0.0036 0.0015
                            children [
                              Box {
                                size 0.032 0.003 0.0365
                              }
                            ]
                            translationStep 0.0001
                          }
                          physics Physics {
                          }
                        }
                      }
                      Shape {
                        appearance PBRAppearance {
                          metalness 0
                        }
                        geometry Mesh {
                          url [
                            "../meshes/wrist2.STL"
                          ]
                        }
                      }
                      Shape {
                        appearance PBRAppearance {
                          baseColor 0.298039 0.298039 0.298039
                          metalness 0
                        }
                        geometry Mesh {
                          url [
                            "../meshes/wrist_2.STL"
                          ]
                        }
                      }
                      Shape {
                        appearance PBRAppearance {
                          baseColor 0.152941 0.152941 0.152941
                          metalness 0
                        }
                        geometry Mesh {
                          url [
                            "../meshes/wrist_2_arm.STL"
                          ]
                        }
                      }
                      Shape {
                        appearance PBRAppearance {
                          baseColor 0.298039 0.298039 0.298039
                          metalness 0
                        }
                        geometry Mesh {
                          url [
                            "../meshes/wrist_2_gripper_motor.STL"
                          ]
                        }
                      }
                    ]
                    boundingObject Group {
                      children [
                        Pose {
                          translation 0.012 -0.001 0
                          children [
                            Box {
                              size 0.043 0.029 0.025
                            }
                          ]
                          translationStep 0.001
                        }
                        Pose {
                          translation 0.1043 -0.001 0.00299966
                          rotation 0 1 0 1.5708
                          children [
                            Cylinder {
                              height 0.137
                              radius 0.0087
                            }
                          ]
                          translationStep 0.0006
                        }
                        Pose {
                          translation 0.25958 0.00986 -0.0018008
                          rotation 0.5773509358554485 0.5773509358554485 0.5773489358556708 2.0944
                          children [
                            Box {
                              size 0.0015 0.0355 0.031
                            }
                          ]
                          translationStep 6e-05
                        }
                        Pose {
                          translation 0.20294 7.99924e-05 -0.00180055
                          rotation 0.5773509358554485 0.5773509358554485 0.5773489358556708 2.0944
                          children [
                            Box {
                              size 0.0229 0.028 0.045
                            }
                          ]
                          translationStep 6e-05
                        }
                      ]
                    }
                    physics Physics {
                    }
                  }
                }
                Shape {
                  appearance PBRAppearance {
                    baseColor 0.654902 0.654902 0.654902
                    metalness 0
                  }
                  geometry Mesh {
                    url [
                      "../meshes/Wrist_motors_washer.STL"
                    ]
                  }
                }
                Shape {
                  appearance PBRAppearance {
                    baseColor 0.152941 0.152941 0.152941
                    metalness 0
                  }
                  geometry Mesh {
                    url [
                      "../meshes/Base_motor_washer_connector.STL"
                    ]
                  }
                }
                Shape {
                  appearance PBRAppearance {
                    baseColor 0.152941 0.152941 0.152941
                    metalness 0
                  }
                  geometry Mesh {
                    url [
                      "../meshes/aluminum_profile.STL"
                    ]
                  }
                }
                Shape {
                  appearance PBRAppearance {
                    baseColor 0.152941 0.152941 0.152941
                    metalness 0
                  }
                  geometry Mesh {
                    url [
                      "../meshes/aluminum_profile_connector.STL"
                    ]
                  }
                }
              ]
              boundingObject Group {
                children [
                  Pose {
                    translation 0 0 0.164
                    children [
                      Box {
                        size 0.021 0.038 0.197
                      }
                    ]
                    translationStep 0.001
                  }
                ]
              }
              physics Physics {
              }
            }
          }
          Shape {
            appearance PBRAppearance {
              baseColor 0.231373 0.231373 0.231373
              metalness 0
            }
            geometry Mesh {
              url [
                "../meshes/Wrist.STL"
              ]
            }
          }
          Shape {
            appearance PBRAppearance {
              baseColor 0.231373 0.231373 0.231373
              metalness 0
            }
            geometry Mesh {
              url [
                "../meshes/Wrist_motors.STL"
              ]
            }
          }
        ]
        name "Wrist"
        boundingObject Pose {
          translation 0 0 0.0257
          children [
            Box {
              size 0.025 0.066 0.045
            }
          ]
          translationStep 0.0002
        }
        physics Physics {
        }
      }
    }
    Shape {
      appearance PBRAppearance {
        baseColor 0.137255 0.137255 0.137255
        metalness 0
      }
      geometry Mesh {
        url [
          "../meshes/Base.STL"
        ]
      }
    }
    Shape {
      appearance PBRAppearance {
        baseColor 0.137255 0.137255 0.137255
        metalness 0
      }
      geometry Mesh {
        url [
          "../meshes/Base2.STL"
        ]
      }
    }
    Shape {
      appearance PBRAppearance {
        baseColor 0.886275 0.592157 0
        metalness 0
      }
      geometry Mesh {
        url [
          "../meshes/Base_standoffs.STL"
        ]
      }
    }
    Shape {
      appearance PBRAppearance {
        baseColor 0.631373 0.627451 0.623529
        metalness 0
      }
      geometry Mesh {
        url [
          "../meshes/Base3.STL"
        ]
      }
    }
    Shape {
      appearance PBRAppearance {
        baseColor 0.168627 0.168627 0.164706
        metalness 0
      }
      geometry Mesh {
        url [
          "../meshes/Base_motor.STL"
        ]
      }
    }
    Shape {
      appearance PBRAppearance {
        baseColor 0.6 0.6 0.584314
        metalness 0
      }
      geometry Mesh {
        url [
          "../meshes/Base_motor_washer.STL"
        ]
      }
    }
    Shape {
      appearance PBRAppearance {
        baseColor 0.6 0.6 0.584314
        metalness 0
      }
      geometry Mesh {
        url [
          "../meshes/Base_motor_Bearing.STL"
        ]
      }
    }
  ]
  name "ROARM"
  boundingObject Group {
    children [
      Pose {
        translation -0.011 0 -0.057
        children [
          Box {
            size 0.09 0.08 0.039
          }
        ]
        translationStep 0.001
      }
      Pose {
        translation 0.008 0 -0.019
        children [
          Box {
            size 0.055 0.042 0.034
          }
        ]
        translationStep 0.001
      }
      Pose {
        translation 0 0 0.004
        children [
          Cylinder {
            height 0.0112
            radius 0.021
          }
        ]
        translationStep 0.001
      }
    ]
  }
  physics Physics {
    density 2000
    mass 5
  }
  controller "roarm_controller"
}
